Workbook

Sheet EMI Calculator
A1: Loan EMI Calculator
A2: Enter loan details in blue cells. All calculations update automatically.
A4: LOAN INPUTS
A5: Loan Amount | B5: 500000 | C5: Principal amount of the loan
A6: Annual Interest Rate (%) | B6: 0.105 | C6: Enter as decimal e.g. 10.5% → 0.105 OR just 10.5
A7: Loan Tenure (Months) | B7: 60 | C7: Number of monthly instalments
A8: Start Date | B8: 2025-01-01 | C8: Loan disbursement date
A10: CALCULATED RESULTS
A11: Monthly EMI (₹) | B11: =IFERROR(PMT(B6/12,B7,-B5),0)
A12: Total Amount Payable (₹) | B12: =IFERROR(B11*B7,0)
A13: Total Interest Payable (₹) | B13: =IFERROR(B12-B5,0)
A14: Interest as % of Principal | B14: =IFERROR(B13/B5,0)
A16: Navneet Priye Chauhan — Finance & Operations Consultant | Free Template: Loan EMI Calculator

Sheet Amortization Schedule
A1: Loan Amortization Schedule
A3: # | B3: Payment Date | C3: Opening Balance (₹) | D3: EMI (₹) | E3: Principal (₹) | F3: Interest (₹) | G3: Closing Balance (₹) | H3: Cumul. Interest (₹) | I3: Cumul. Principal (₹)
A4: 1 | B4: ='EMI Calculator'!B8 | C4: ='EMI Calculator'!B5 | D4: ='EMI Calculator'!B11 | E4: =IFERROR(D4-F4,0) | F4: =IFERROR(C4*'EMI Calculator'!B6/12,0) | G4: =IFERROR(C4-E4,0) | H4: =F4 | I4: =E4
A5: 2 | B5: =IFERROR(DATE(YEAR(B4),MONTH(B4)+1,DAY(B4)),"") | C5: =IFERROR(IF(A5<='EMI Calculator'!B7,G4,""),"") | D5: =IFERROR(IF(A5<='EMI Calculator'!B7,'EMI Calculator'!B11,""),"") | E5: =IFERROR(IF(A5<='EMI Calculator'!B7,D5-F5,""),"") | F5: =IFERROR(IF(A5<='EMI Calculator'!B7,C5*'EMI Calculator'!B6/12,""),"") | G5: =IFERROR(IF(A5<='EMI Calculator'!B7,MAX(C5-E5,0),""),"") | H5: =IFERROR(IF(A5<='EMI Calculator'!B7,H4+F5,""),"") | I5: =IFERROR(IF(A5<='EMI Calculator'!B7,I4+E5,""),"")
A6: 3 | B6: =IFERROR(DATE(YEAR(B5),MONTH(B5)+1,DAY(B5)),"") | C6: =IFERROR(IF(A6<='EMI Calculator'!B7,G5,""),"") | D6: =IFERROR(IF(A6<='EMI Calculator'!B7,'EMI Calculator'!B11,""),"") | E6: =IFERROR(IF(A6<='EMI Calculator'!B7,D6-F6,""),"") | F6: =IFERROR(IF(A6<='EMI Calculator'!B7,C6*'EMI Calculator'!B6/12,""),"") | G6: =IFERROR(IF(A6<='EMI Calculator'!B7,MAX(C6-E6,0),""),"") | H6: =IFERROR(IF(A6<='EMI Calculator'!B7,H5+F6,""),"") | I6: =IFERROR(IF(A6<='EMI Calculator'!B7,I5+E6,""),"")
A7: 4 | B7: =IFERROR(DATE(YEAR(B6),MONTH(B6)+1,DAY(B6)),"") | C7: =IFERROR(IF(A7<='EMI Calculator'!B7,G6,""),"") | D7: =IFERROR(IF(A7<='EMI Calculator'!B7,'EMI Calculator'!B11,""),"") | E7: =IFERROR(IF(A7<='EMI Calculator'!B7,D7-F7,""),"") | F7: =IFERROR(IF(A7<='EMI Calculator'!B7,C7*'EMI Calculator'!B6/12,""),"") | G7: =IFERROR(IF(A7<='EMI Calculator'!B7,MAX(C7-E7,0),""),"") | H7: =IFERROR(IF(A7<='EMI Calculator'!B7,H6+F7,""),"") | I7: =IFERROR(IF(A7<='EMI Calculator'!B7,I6+E7,""),"")
A8: 5 | B8: =IFERROR(DATE(YEAR(B7),MONTH(B7)+1,DAY(B7)),"") | C8: =IFERROR(IF(A8<='EMI Calculator'!B7,G7,""),"") | D8: =IFERROR(IF(A8<='EMI Calculator'!B7,'EMI Calculator'!B11,""),"") | E8: =IFERROR(IF(A8<='EMI Calculator'!B7,D8-F8,""),"") | F8: =IFERROR(IF(A8<='EMI Calculator'!B7,C8*'EMI Calculator'!B6/12,""),"") | G8: =IFERROR(IF(A8<='EMI Calculator'!B7,MAX(C8-E8,0),""),"") | H8: =IFERROR(IF(A8<='EMI Calculator'!B7,H7+F8,""),"") | I8: =IFERROR(IF(A8<='EMI Calculator'!B7,I7+E8,""),"")
A9: 6 | B9: =IFERROR(DATE(YEAR(B8),MONTH(B8)+1,DAY(B8)),"") | C9: =IFERROR(IF(A9<='EMI Calculator'!B7,G8,""),"") | D9: =IFERROR(IF(A9<='EMI Calculator'!B7,'EMI Calculator'!B11,""),"") | E9: =IFERROR(IF(A9<='EMI Calculator'!B7,D9-F9,""),"") | F9: =IFERROR(IF(A9<='EMI Calculator'!B7,C9*'EMI Calculator'!B6/12,""),"") | G9: =IFERROR(IF(A9<='EMI Calculator'!B7,MAX(C9-E9,0),""),"") | H9: =IFERROR(IF(A9<='EMI Calculator'!B7,H8+F9,""),"") | I9: =IFERROR(IF(A9<='EMI Calculator'!B7,I8+E9,""),"")
A10: 7 | B10: =IFERROR(DATE(YEAR(B9),MONTH(B9)+1,DAY(B9)),"") | C10: =IFERROR(IF(A10<='EMI Calculator'!B7,G9,""),"") | D10: =IFERROR(IF(A10<='EMI Calculator'!B7,'EMI Calculator'!B11,""),"") | E10: =IFERROR(IF(A10<='EMI Calculator'!B7,D10-F10,""),"") | F10: =IFERROR(IF(A10<='EMI Calculator'!B7,C10*'EMI Calculator'!B6/12,""),"") | G10: =IFERROR(IF(A10<='EMI Calculator'!B7,MAX(C10-E10,0),""),"") | H10: =IFERROR(IF(A10<='EMI Calculator'!B7,H9+F10,""),"") | I10: =IFERROR(IF(A10<='EMI Calculator'!B7,I9+E10,""),"")
A11: 8 | B11: =IFERROR(DATE(YEAR(B10),MONTH(B10)+1,DAY(B10)),"") | C11: =IFERROR(IF(A11<='EMI Calculator'!B7,G10,""),"") | D11: =IFERROR(IF(A11<='EMI Calculator'!B7,'EMI Calculator'!B11,""),"") | E11: =IFERROR(IF(A11<='EMI Calculator'!B7,D11-F11,""),"") | F11: =IFERROR(IF(A11<='EMI Calculator'!B7,C11*'EMI Calculator'!B6/12,""),"") | G11: =IFERROR(IF(A11<='EMI Calculator'!B7,MAX(C11-E11,0),""),"") | H11: =IFERROR(IF(A11<='EMI Calculator'!B7,H10+F11,""),"") | I11: =IFERROR(IF(A11<='EMI Calculator'!B7,I10+E11,""),"")
A12: 9 | B12: =IFERROR(DATE(YEAR(B11),MONTH(B11)+1,DAY(B11)),"") | C12: =IFERROR(IF(A12<='EMI Calculator'!B7,G11,""),"") | D12: =IFERROR(IF(A12<='EMI Calculator'!B7,'EMI Calculator'!B11,""),"") | E12: =IFERROR(IF(A12<='EMI Calculator'!B7,D12-F12,""),"") | F12: =IFERROR(IF(A12<='EMI Calculator'!B7,C12*'EMI Calculator'!B6/12,""),"") | G12: =IFERROR(IF(A12<='EMI Calculator'!B7,MAX(C12-E12,0),""),"") | H12: =IFERROR(IF(A12<='EMI Calculator'!B7,H11+F12,""),"") | I12: =IFERROR(IF(A12<='EMI Calculator'!B7,I11+E12,""),"")
A13: 10 | B13: =IFERROR(DATE(YEAR(B12),MONTH(B12)+1,DAY(B12)),"") | C13: =IFERROR(IF(A13<='EMI Calculator'!B7,G12,""),"") | D13: =IFERROR(IF(A13<='EMI Calculator'!B7,'EMI Calculator'!B11,""),"") | E13: =IFERROR(IF(A13<='EMI Calculator'!B7,D13-F13,""),"") | F13: =IFERROR(IF(A13<='EMI Calculator'!B7,C13*'EMI Calculator'!B6/12,""),"") | G13: =IFERROR(IF(A13<='EMI Calculator'!B7,MAX(C13-E13,0),""),"") | H13: =IFERROR(IF(A13<='EMI Calculator'!B7,H12+F13,""),"") | I13: =IFERROR(IF(A13<='EMI Calculator'!B7,I12+E13,""),"")
A14: 11 | B14: =IFERROR(DATE(YEAR(B13),MONTH(B13)+1,DAY(B13)),"") | C14: =IFERROR(IF(A14<='EMI Calculator'!B7,G13,""),"") | D14: =IFERROR(IF(A14<='EMI Calculator'!B7,'EMI Calculator'!B11,""),"") | E14: =IFERROR(IF(A14<='EMI Calculator'!B7,D14-F14,""),"") | F14: =IFERROR(IF(A14<='EMI Calculator'!B7,C14*'EMI Calculator'!B6/12,""),"") | G14: =IFERROR(IF(A14<='EMI Calculator'!B7,MAX(C14-E14,0),""),"") | H14: =IFERROR(IF(A14<='EMI Calculator'!B7,H13+F14,""),"") | I14: =IFERROR(IF(A14<='EMI Calculator'!B7,I13+E14,""),"")
A15: 12 | B15: =IFERROR(DATE(YEAR(B14),MONTH(B14)+1,DAY(B14)),"") | C15: =IFERROR(IF(A15<='EMI Calculator'!B7,G14,""),"") | D15: =IFERROR(IF(A15<='EMI Calculator'!B7,'EMI Calculator'!B11,""),"") | E15: =IFERROR(IF(A15<='EMI Calculator'!B7,D15-F15,""),"") | F15: =IFERROR(IF(A15<='EMI Calculator'!B7,C15*'EMI Calculator'!B6/12,""),"") | G15: =IFERROR(IF(A15<='EMI Calculator'!B7,MAX(C15-E15,0),""),"") | H15: =IFERROR(IF(A15<='EMI Calculator'!B7,H14+F15,""),"") | I15: =IFERROR(IF(A15<='EMI Calculator'!B7,I14+E15,""),"")
A16: 13 | B16: =IFERROR(DATE(YEAR(B15),MONTH(B15)+1,DAY(B15)),"") | C16: =IFERROR(IF(A16<='EMI Calculator'!B7,G15,""),"") | D16: =IFERROR(IF(A16<='EMI Calculator'!B7,'EMI Calculator'!B11,""),"") | E16: =IFERROR(IF(A16<='EMI Calculator'!B7,D16-F16,""),"") | F16: =IFERROR(IF(A16<='EMI Calculator'!B7,C16*'EMI Calculator'!B6/12,""),"") | G16: =IFERROR(IF(A16<='EMI Calculator'!B7,MAX(C16-E16,0),""),"") | H16: =IFERROR(IF(A16<='EMI Calculator'!B7,H15+F16,""),"") | I16: =IFERROR(IF(A16<='EMI Calculator'!B7,I15+E16,""),"")
A17: 14 | B17: =IFERROR(DATE(YEAR(B16),MONTH(B16)+1,DAY(B16)),"") | C17: =IFERROR(IF(A17<='EMI Calculator'!B7,G16,""),"") | D17: =IFERROR(IF(A17<='EMI Calculator'!B7,'EMI Calculator'!B11,""),"") | E17: =IFERROR(IF(A17<='EMI Calculator'!B7,D17-F17,""),"") | F17: =IFERROR(IF(A17<='EMI Calculator'!B7,C17*'EMI Calculator'!B6/12,""),"") | G17: =IFERROR(IF(A17<='EMI Calculator'!B7,MAX(C17-E17,0),""),"") | H17: =IFERROR(IF(A17<='EMI Calculator'!B7,H16+F17,""),"") | I17: =IFERROR(IF(A17<='EMI Calculator'!B7,I16+E17,""),"")
A18: 15 | B18: =IFERROR(DATE(YEAR(B17),MONTH(B17)+1,DAY(B17)),"") | C18: =IFERROR(IF(A18<='EMI Calculator'!B7,G17,""),"") | D18: =IFERROR(IF(A18<='EMI Calculator'!B7,'EMI Calculator'!B11,""),"") | E18: =IFERROR(IF(A18<='EMI Calculator'!B7,D18-F18,""),"") | F18: =IFERROR(IF(A18<='EMI Calculator'!B7,C18*'EMI Calculator'!B6/12,""),"") | G18: =IFERROR(IF(A18<='EMI Calculator'!B7,MAX(C18-E18,0),""),"") | H18: =IFERROR(IF(A18<='EMI Calculator'!B7,H17+F18,""),"") | I18: =IFERROR(IF(A18<='EMI Calculator'!B7,I17+E18,""),"")
A19: 16 | B19: =IFERROR(DATE(YEAR(B18),MONTH(B18)+1,DAY(B18)),"") | C19: =IFERROR(IF(A19<='EMI Calculator'!B7,G18,""),"") | D19: =IFERROR(IF(A19<='EMI Calculator'!B7,'EMI Calculator'!B11,""),"") | E19: =IFERROR(IF(A19<='EMI Calculator'!B7,D19-F19,""),"") | F19: =IFERROR(IF(A19<='EMI Calculator'!B7,C19*'EMI Calculator'!B6/12,""),"") | G19: =IFERROR(IF(A19<='EMI Calculator'!B7,MAX(C19-E19,0),""),"") | H19: =IFERROR(IF(A19<='EMI Calculator'!B7,H18+F19,""),"") | I19: =IFERROR(IF(A19<='EMI Calculator'!B7,I18+E19,""),"")
A20: 17 | B20: =IFERROR(DATE(YEAR(B19),MONTH(B19)+1,DAY(B19)),"") | C20: =IFERROR(IF(A20<='EMI Calculator'!B7,G19,""),"") | D20: =IFERROR(IF(A20<='EMI Calculator'!B7,'EMI Calculator'!B11,""),"") | E20: =IFERROR(IF(A20<='EMI Calculator'!B7,D20-F20,""),"") | F20: =IFERROR(IF(A20<='EMI Calculator'!B7,C20*'EMI Calculator'!B6/12,""),"") | G20: =IFERROR(IF(A20<='EMI Calculator'!B7,MAX(C20-E20,0),""),"") | H20: =IFERROR(IF(A20<='EMI Calculator'!B7,H19+F20,""),"") | I20: =IFERROR(IF(A20<='EMI Calculator'!B7,I19+E20,""),"")
A21: 18 | B21: =IFERROR(DATE(YEAR(B20),MONTH(B20)+1,DAY(B20)),"") | C21: =IFERROR(IF(A21<='EMI Calculator'!B7,G20,""),"") | D21: =IFERROR(IF(A21<='EMI Calculator'!B7,'EMI Calculator'!B11,""),"") | E21: =IFERROR(IF(A21<='EMI Calculator'!B7,D21-F21,""),"") | F21: =IFERROR(IF(A21<='EMI Calculator'!B7,C21*'EMI Calculator'!B6/12,""),"") | G21: =IFERROR(IF(A21<='EMI Calculator'!B7,MAX(C21-E21,0),""),"") | H21: =IFERROR(IF(A21<='EMI Calculator'!B7,H20+F21,""),"") | I21: =IFERROR(IF(A21<='EMI Calculator'!B7,I20+E21,""),"")
A22: 19 | B22: =IFERROR(DATE(YEAR(B21),MONTH(B21)+1,DAY(B21)),"") | C22: =IFERROR(IF(A22<='EMI Calculator'!B7,G21,""),"") | D22: =IFERROR(IF(A22<='EMI Calculator'!B7,'EMI Calculator'!B11,""),"") | E22: =IFERROR(IF(A22<='EMI Calculator'!B7,D22-F22,""),"") | F22: =IFERROR(IF(A22<='EMI Calculator'!B7,C22*'EMI Calculator'!B6/12,""),"") | G22: =IFERROR(IF(A22<='EMI Calculator'!B7,MAX(C22-E22,0),""),"") | H22: =IFERROR(IF(A22<='EMI Calculator'!B7,H21+F22,""),"") | I22: =IFERROR(IF(A22<='EMI Calculator'!B7,I21+E22,""),"")
A23: 20 | B23: =IFERROR(DATE(YEAR(B22),MONTH(B22)+1,DAY(B22)),"") | C23: =IFERROR(IF(A23<='EMI Calculator'!B7,G22,""),"") | D23: =IFERROR(IF(A23<='EMI Calculator'!B7,'EMI Calculator'!B11,""),"") | E23: =IFERROR(IF(A23<='EMI Calculator'!B7,D23-F23,""),"") | F23: =IFERROR(IF(A23<='EMI Calculator'!B7,C23*'EMI Calculator'!B6/12,""),"") | G23: =IFERROR(IF(A23<='EMI Calculator'!B7,MAX(C23-E23,0),""),"") | H23: =IFERROR(IF(A23<='EMI Calculator'!B7,H22+F23,""),"") | I23: =IFERROR(IF(A23<='EMI Calculator'!B7,I22+E23,""),"")
A24: 21 | B24: =IFERROR(DATE(YEAR(B23),MONTH(B23)+1,DAY(B23)),"") | C24: =IFERROR(IF(A24<='EMI Calculator'!B7,G23,""),"") | D24: =IFERROR(IF(A24<='EMI Calculator'!B7,'EMI Calculator'!B11,""),"") | E24: =IFERROR(IF(A24<='EMI Calculator'!B7,D24-F24,""),"") | F24: =IFERROR(IF(A24<='EMI Calculator'!B7,C24*'EMI Calculator'!B6/12,""),"") | G24: =IFERROR(IF(A24<='EMI Calculator'!B7,MAX(C24-E24,0),""),"") | H24: =IFERROR(IF(A24<='EMI Calculator'!B7,H23+F24,""),"") | I24: =IFERROR(IF(A24<='EMI Calculator'!B7,I23+E24,""),"")
A25: 22 | B25: =IFERROR(DATE(YEAR(B24),MONTH(B24)+1,DAY(B24)),"") | C25: =IFERROR(IF(A25<='EMI Calculator'!B7,G24,""),"") | D25: =IFERROR(IF(A25<='EMI Calculator'!B7,'EMI Calculator'!B11,""),"") | E25: =IFERROR(IF(A25<='EMI Calculator'!B7,D25-F25,""),"") | F25: =IFERROR(IF(A25<='EMI Calculator'!B7,C25*'EMI Calculator'!B6/12,""),"") | G25: =IFERROR(IF(A25<='EMI Calculator'!B7,MAX(C25-E25,0),""),"") | H25: =IFERROR(IF(A25<='EMI Calculator'!B7,H24+F25,""),"") | I25: =IFERROR(IF(A25<='EMI Calculator'!B7,I24+E25,""),"")
A26: 23 | B26: =IFERROR(DATE(YEAR(B25),MONTH(B25)+1,DAY(B25)),"") | C26: =IFERROR(IF(A26<='EMI Calculator'!B7,G25,""),"") | D26: =IFERROR(IF(A26<='EMI Calculator'!B7,'EMI Calculator'!B11,""),"") | E26: =IFERROR(IF(A26<='EMI Calculator'!B7,D26-F26,""),"") | F26: =IFERROR(IF(A26<='EMI Calculator'!B7,C26*'EMI Calculator'!B6/12,""),"") | G26: =IFERROR(IF(A26<='EMI Calculator'!B7,MAX(C26-E26,0),""),"") | H26: =IFERROR(IF(A26<='EMI Calculator'!B7,H25+F26,""),"") | I26: =IFERROR(IF(A26<='EMI Calculator'!B7,I25+E26,""),"")
A27: 24 | B27: =IFERROR(DATE(YEAR(B26),MONTH(B26)+1,DAY(B26)),"") | C27: =IFERROR(IF(A27<='EMI Calculator'!B7,G26,""),"") | D27: =IFERROR(IF(A27<='EMI Calculator'!B7,'EMI Calculator'!B11,""),"") | E27: =IFERROR(IF(A27<='EMI Calculator'!B7,D27-F27,""),"") | F27: =IFERROR(IF(A27<='EMI Calculator'!B7,C27*'EMI Calculator'!B6/12,""),"") | G27: =IFERROR(IF(A27<='EMI Calculator'!B7,MAX(C27-E27,0),""),"") | H27: =IFERROR(IF(A27<='EMI Calculator'!B7,H26+F27,""),"") | I27: =IFERROR(IF(A27<='EMI Calculator'!B7,I26+E27,""),"")
A28: 25 | B28: =IFERROR(DATE(YEAR(B27),MONTH(B27)+1,DAY(B27)),"") | C28: =IFERROR(IF(A28<='EMI Calculator'!B7,G27,""),"") | D28: =IFERROR(IF(A28<='EMI Calculator'!B7,'EMI Calculator'!B11,""),"") | E28: =IFERROR(IF(A28<='EMI Calculator'!B7,D28-F28,""),"") | F28: =IFERROR(IF(A28<='EMI Calculator'!B7,C28*'EMI Calculator'!B6/12,""),"") | G28: =IFERROR(IF(A28<='EMI Calculator'!B7,MAX(C28-E28,0),""),"") | H28: =IFERROR(IF(A28<='EMI Calculator'!B7,H27+F28,""),"") | I28: =IFERROR(IF(A28<='EMI Calculator'!B7,I27+E28,""),"")
A29: 26 | B29: =IFERROR(DATE(YEAR(B28),MONTH(B28)+1,DAY(B28)),"") | C29: =IFERROR(IF(A29<='EMI Calculator'!B7,G28,""),"") | D29: =IFERROR(IF(A29<='EMI Calculator'!B7,'EMI Calculator'!B11,""),"") | E29: =IFERROR(IF(A29<='EMI Calculator'!B7,D29-F29,""),"") | F29: =IFERROR(IF(A29<='EMI Calculator'!B7,C29*'EMI Calculator'!B6/12,""),"") | G29: =IFERROR(IF(A29<='EMI Calculator'!B7,MAX(C29-E29,0),""),"") | H29: =IFERROR(IF(A29<='EMI Calculator'!B7,H28+F29,""),"") | I29: =IFERROR(IF(A29<='EMI Calculator'!B7,I28+E29,""),"")
A30: 27 | B30: =IFERROR(DATE(YEAR(B29),MONTH(B29)+1,DAY(B29)),"") | C30: =IFERROR(IF(A30<='EMI Calculator'!B7,G29,""),"") | D30: =IFERROR(IF(A30<='EMI Calculator'!B7,'EMI Calculator'!B11,""),"") | E30: =IFERROR(IF(A30<='EMI Calculator'!B7,D30-F30,""),"") | F30: =IFERROR(IF(A30<='EMI Calculator'!B7,C30*'EMI Calculator'!B6/12,""),"") | G30: =IFERROR(IF(A30<='EMI Calculator'!B7,MAX(C30-E30,0),""),"") | H30: =IFERROR(IF(A30<='EMI Calculator'!B7,H29+F30,""),"") | I30: =IFERROR(IF(A30<='EMI Calculator'!B7,I29+E30,""),"")
A31: 28 | B31: =IFERROR(DATE(YEAR(B30),MONTH(B30)+1,DAY(B30)),"") | C31: =IFERROR(IF(A31<='EMI Calculator'!B7,G30,""),"") | D31: =IFERROR(IF(A31<='EMI Calculator'!B7,'EMI Calculator'!B11,""),"") | E31: =IFERROR(IF(A31<='EMI Calculator'!B7,D31-F31,""),"") | F31: =IFERROR(IF(A31<='EMI Calculator'!B7,C31*'EMI Calculator'!B6/12,""),"") | G31: =IFERROR(IF(A31<='EMI Calculator'!B7,MAX(C31-E31,0),""),"") | H31: =IFERROR(IF(A31<='EMI Calculator'!B7,H30+F31,""),"") | I31: =IFERROR(IF(A31<='EMI Calculator'!B7,I30+E31,""),"")
A32: 29 | B32: =IFERROR(DATE(YEAR(B31),MONTH(B31)+1,DAY(B31)),"") | C32: =IFERROR(IF(A32<='EMI Calculator'!B7,G31,""),"") | D32: =IFERROR(IF(A32<='EMI Calculator'!B7,'EMI Calculator'!B11,""),"") | E32: =IFERROR(IF(A32<='EMI Calculator'!B7,D32-F32,""),"") | F32: =IFERROR(IF(A32<='EMI Calculator'!B7,C32*'EMI Calculator'!B6/12,""),"") | G32: =IFERROR(IF(A32<='EMI Calculator'!B7,MAX(C32-E32,0),""),"") | H32: =IFERROR(IF(A32<='EMI Calculator'!B7,H31+F32,""),"") | I32: =IFERROR(IF(A32<='EMI Calculator'!B7,I31+E32,""),"")
A33: 30 | B33: =IFERROR(DATE(YEAR(B32),MONTH(B32)+1,DAY(B32)),"") | C33: =IFERROR(IF(A33<='EMI Calculator'!B7,G32,""),"") | D33: =IFERROR(IF(A33<='EMI Calculator'!B7,'EMI Calculator'!B11,""),"") | E33: =IFERROR(IF(A33<='EMI Calculator'!B7,D33-F33,""),"") | F33: =IFERROR(IF(A33<='EMI Calculator'!B7,C33*'EMI Calculator'!B6/12,""),"") | G33: =IFERROR(IF(A33<='EMI Calculator'!B7,MAX(C33-E33,0),""),"") | H33: =IFERROR(IF(A33<='EMI Calculator'!B7,H32+F33,""),"") | I33: =IFERROR(IF(A33<='EMI Calculator'!B7,I32+E33,""),"")
A34: 31 | B34: =IFERROR(DATE(YEAR(B33),MONTH(B33)+1,DAY(B33)),"") | C34: =IFERROR(IF(A34<='EMI Calculator'!B7,G33,""),"") | D34: =IFERROR(IF(A34<='EMI Calculator'!B7,'EMI Calculator'!B11,""),"") | E34: =IFERROR(IF(A34<='EMI Calculator'!B7,D34-F34,""),"") | F34: =IFERROR(IF(A34<='EMI Calculator'!B7,C34*'EMI Calculator'!B6/12,""),"") | G34: =IFERROR(IF(A34<='EMI Calculator'!B7,MAX(C34-E34,0),""),"") | H34: =IFERROR(IF(A34<='EMI Calculator'!B7,H33+F34,""),"") | I34: =IFERROR(IF(A34<='EMI Calculator'!B7,I33+E34,""),"")
A35: 32 | B35: =IFERROR(DATE(YEAR(B34),MONTH(B34)+1,DAY(B34)),"") | C35: =IFERROR(IF(A35<='EMI Calculator'!B7,G34,""),"") | D35: =IFERROR(IF(A35<='EMI Calculator'!B7,'EMI Calculator'!B11,""),"") | E35: =IFERROR(IF(A35<='EMI Calculator'!B7,D35-F35,""),"") | F35: =IFERROR(IF(A35<='EMI Calculator'!B7,C35*'EMI Calculator'!B6/12,""),"") | G35: =IFERROR(IF(A35<='EMI Calculator'!B7,MAX(C35-E35,0),""),"") | H35: =IFERROR(IF(A35<='EMI Calculator'!B7,H34+F35,""),"") | I35: =IFERROR(IF(A35<='EMI Calculator'!B7,I34+E35,""),"")
A36: 33 | B36: =IFERROR(DATE(YEAR(B35),MONTH(B35)+1,DAY(B35)),"") | C36: =IFERROR(IF(A36<='EMI Calculator'!B7,G35,""),"") | D36: =IFERROR(IF(A36<='EMI Calculator'!B7,'EMI Calculator'!B11,""),"") | E36: =IFERROR(IF(A36<='EMI Calculator'!B7,D36-F36,""),"") | F36: =IFERROR(IF(A36<='EMI Calculator'!B7,C36*'EMI Calculator'!B6/12,""),"") | G36: =IFERROR(IF(A36<='EMI Calculator'!B7,MAX(C36-E36,0),""),"") | H36: =IFERROR(IF(A36<='EMI Calculator'!B7,H35+F36,""),"") | I36: =IFERROR(IF(A36<='EMI Calculator'!B7,I35+E36,""),"")
A37: 34 | B37: =IFERROR(DATE(YEAR(B36),MONTH(B36)+1,DAY(B36)),"") | C37: =IFERROR(IF(A37<='EMI Calculator'!B7,G36,""),"") | D37: =IFERROR(IF(A37<='EMI Calculator'!B7,'EMI Calculator'!B11,""),"") | E37: =IFERROR(IF(A37<='EMI Calculator'!B7,D37-F37,""),"") | F37: =IFERROR(IF(A37<='EMI Calculator'!B7,C37*'EMI Calculator'!B6/12,""),"") | G37: =IFERROR(IF(A37<='EMI Calculator'!B7,MAX(C37-E37,0),""),"") | H37: =IFERROR(IF(A37<='EMI Calculator'!B7,H36+F37,""),"") | I37: =IFERROR(IF(A37<='EMI Calculator'!B7,I36+E37,""),"")
A38: 35 | B38: =IFERROR(DATE(YEAR(B37),MONTH(B37)+1,DAY(B37)),"") | C38: =IFERROR(IF(A38<='EMI Calculator'!B7,G37,""),"") | D38: =IFERROR(IF(A38<='EMI Calculator'!B7,'EMI Calculator'!B11,""),"") | E38: =IFERROR(IF(A38<='EMI Calculator'!B7,D38-F38,""),"") | F38: =IFERROR(IF(A38<='EMI Calculator'!B7,C38*'EMI Calculator'!B6/12,""),"") | G38: =IFERROR(IF(A38<='EMI Calculator'!B7,MAX(C38-E38,0),""),"") | H38: =IFERROR(IF(A38<='EMI Calculator'!B7,H37+F38,""),"") | I38: =IFERROR(IF(A38<='EMI Calculator'!B7,I37+E38,""),"")
A39: 36 | B39: =IFERROR(DATE(YEAR(B38),MONTH(B38)+1,DAY(B38)),"") | C39: =IFERROR(IF(A39<='EMI Calculator'!B7,G38,""),"") | D39: =IFERROR(IF(A39<='EMI Calculator'!B7,'EMI Calculator'!B11,""),"") | E39: =IFERROR(IF(A39<='EMI Calculator'!B7,D39-F39,""),"") | F39: =IFERROR(IF(A39<='EMI Calculator'!B7,C39*'EMI Calculator'!B6/12,""),"") | G39: =IFERROR(IF(A39<='EMI Calculator'!B7,MAX(C39-E39,0),""),"") | H39: =IFERROR(IF(A39<='EMI Calculator'!B7,H38+F39,""),"") | I39: =IFERROR(IF(A39<='EMI Calculator'!B7,I38+E39,""),"")
A40: 37 | B40: =IFERROR(DATE(YEAR(B39),MONTH(B39)+1,DAY(B39)),"") | C40: =IFERROR(IF(A40<='EMI Calculator'!B7,G39,""),"") | D40: =IFERROR(IF(A40<='EMI Calculator'!B7,'EMI Calculator'!B11,""),"") | E40: =IFERROR(IF(A40<='EMI Calculator'!B7,D40-F40,""),"") | F40: =IFERROR(IF(A40<='EMI Calculator'!B7,C40*'EMI Calculator'!B6/12,""),"") | G40: =IFERROR(IF(A40<='EMI Calculator'!B7,MAX(C40-E40,0),""),"") | H40: =IFERROR(IF(A40<='EMI Calculator'!B7,H39+F40,""),"") | I40: =IFERROR(IF(A40<='EMI Calculator'!B7,I39+E40,""),"")
A41: 38 | B41: =IFERROR(DATE(YEAR(B40),MONTH(B40)+1,DAY(B40)),"") | C41: =IFERROR(IF(A41<='EMI Calculator'!B7,G40,""),"") | D41: =IFERROR(IF(A41<='EMI Calculator'!B7,'EMI Calculator'!B11,""),"") | E41: =IFERROR(IF(A41<='EMI Calculator'!B7,D41-F41,""),"") | F41: =IFERROR(IF(A41<='EMI Calculator'!B7,C41*'EMI Calculator'!B6/12,""),"") | G41: =IFERROR(IF(A41<='EMI Calculator'!B7,MAX(C41-E41,0),""),"") | H41: =IFERROR(IF(A41<='EMI Calculator'!B7,H40+F41,""),"") | I41: =IFERROR(IF(A41<='EMI Calculator'!B7,I40+E41,""),"")
...
